[2023-03-04T15:08:16.553+0000] {taskinstance.py:1083} INFO - Dependencies all met for <TaskInstance: sl_covid_dag_v1.extract manual__2023-03-04T15:06:13.022119+00:00 [queued]>
[2023-03-04T15:08:16.586+0000] {taskinstance.py:1083} INFO - Dependencies all met for <TaskInstance: sl_covid_dag_v1.extract manual__2023-03-04T15:06:13.022119+00:00 [queued]>
[2023-03-04T15:08:16.596+0000] {taskinstance.py:1279} INFO - 
--------------------------------------------------------------------------------
[2023-03-04T15:08:16.597+0000] {taskinstance.py:1280} INFO - Starting attempt 2 of 6
[2023-03-04T15:08:16.616+0000] {taskinstance.py:1281} INFO - 
--------------------------------------------------------------------------------
[2023-03-04T15:08:16.633+0000] {taskinstance.py:1300} INFO - Executing <Task(PythonOperator): extract> on 2023-03-04 15:06:13.022119+00:00
[2023-03-04T15:08:16.638+0000] {standard_task_runner.py:55} INFO - Started process 1199 to run task
[2023-03-04T15:08:16.642+0000] {standard_task_runner.py:82} INFO - Running: ['***', 'tasks', 'run', 'sl_covid_dag_v1', 'extract', 'manual__2023-03-04T15:06:13.022119+00:00', '--job-id', '22', '--raw', '--subdir', 'DAGS_FOLDER/sl_covid_dag.py', '--cfg-path', '/tmp/tmp5axq1b3f']
[2023-03-04T15:08:16.644+0000] {standard_task_runner.py:83} INFO - Job 22: Subtask extract
[2023-03-04T15:08:16.715+0000] {task_command.py:388} INFO - Running <TaskInstance: sl_covid_dag_v1.extract manual__2023-03-04T15:06:13.022119+00:00 [running]> on host 00dcc0a33b20
[2023-03-04T15:08:16.797+0000] {taskinstance.py:1509} INFO - Exporting the following env vars:
AIRFLOW_CTX_DAG_OWNER=ishok
AIRFLOW_CTX_DAG_ID=sl_covid_dag_v1
AIRFLOW_CTX_TASK_ID=extract
AIRFLOW_CTX_EXECUTION_DATE=2023-03-04T15:06:13.022119+00:00
AIRFLOW_CTX_TRY_NUMBER=2
AIRFLOW_CTX_DAG_RUN_ID=manual__2023-03-04T15:06:13.022119+00:00
[2023-03-04T15:08:16.800+0000] {taskinstance.py:1768} ERROR - Task failed with exception
Traceback (most recent call last):
  File "/home/airflow/.local/lib/python3.7/site-packages/airflow/operators/python.py", line 175, in execute
    return_value = self.execute_callable()
  File "/home/airflow/.local/lib/python3.7/site-packages/airflow/operators/python.py", line 192, in execute_callable
    return self.python_callable(*self.op_args, **self.op_kwargs)
  File "/opt/airflow/dags/sl_covid_dag.py", line 15, in extract
    covid = pd.read_excel(spreadsheet_name)
  File "/home/airflow/.local/lib/python3.7/site-packages/pandas/util/_decorators.py", line 311, in wrapper
    return func(*args, **kwargs)
  File "/home/airflow/.local/lib/python3.7/site-packages/pandas/io/excel/_base.py", line 364, in read_excel
    io = ExcelFile(io, storage_options=storage_options, engine=engine)
  File "/home/airflow/.local/lib/python3.7/site-packages/pandas/io/excel/_base.py", line 1192, in __init__
    content_or_path=path_or_buffer, storage_options=storage_options
  File "/home/airflow/.local/lib/python3.7/site-packages/pandas/io/excel/_base.py", line 1071, in inspect_excel_format
    content_or_path, "rb", storage_options=storage_options, is_text=False
  File "/home/airflow/.local/lib/python3.7/site-packages/pandas/io/common.py", line 711, in get_handle
    handle = open(handle, ioargs.mode)
FileNotFoundError: [Errno 2] No such file or directory: './data/sierra-leone_covid-19.xlsx'
[2023-03-04T15:08:16.812+0000] {taskinstance.py:1323} INFO - Marking task as UP_FOR_RETRY. dag_id=sl_covid_dag_v1, task_id=extract, execution_date=20230304T150613, start_date=20230304T150816, end_date=20230304T150816
[2023-03-04T15:08:16.824+0000] {standard_task_runner.py:105} ERROR - Failed to execute job 22 for task extract ([Errno 2] No such file or directory: './data/sierra-leone_covid-19.xlsx'; 1199)
[2023-03-04T15:08:16.857+0000] {local_task_job.py:208} INFO - Task exited with return code 1
[2023-03-04T15:08:16.898+0000] {taskinstance.py:2578} INFO - 0 downstream tasks scheduled from follow-on schedule check
