[2023-03-05T00:36:24.425+0000] {taskinstance.py:1083} INFO - Dependencies all met for <TaskInstance: sl_covid_dag_v1.extract scheduled__2023-03-04T00:00:00+00:00 [queued]>
[2023-03-05T00:36:24.467+0000] {taskinstance.py:1083} INFO - Dependencies all met for <TaskInstance: sl_covid_dag_v1.extract scheduled__2023-03-04T00:00:00+00:00 [queued]>
[2023-03-05T00:36:24.469+0000] {taskinstance.py:1279} INFO - 
--------------------------------------------------------------------------------
[2023-03-05T00:36:24.472+0000] {taskinstance.py:1280} INFO - Starting attempt 6 of 6
[2023-03-05T00:36:24.474+0000] {taskinstance.py:1281} INFO - 
--------------------------------------------------------------------------------
[2023-03-05T00:36:24.523+0000] {taskinstance.py:1300} INFO - Executing <Task(PythonOperator): extract> on 2023-03-04 00:00:00+00:00
[2023-03-05T00:36:24.539+0000] {standard_task_runner.py:55} INFO - Started process 30770 to run task
[2023-03-05T00:36:24.550+0000] {standard_task_runner.py:82} INFO - Running: ['***', 'tasks', 'run', 'sl_covid_dag_v1', 'extract', 'scheduled__2023-03-04T00:00:00+00:00', '--job-id', '39', '--raw', '--subdir', 'DAGS_FOLDER/sl_covid_dag.py', '--cfg-path', '/tmp/tmphqgjtoyc']
[2023-03-05T00:36:24.557+0000] {standard_task_runner.py:83} INFO - Job 39: Subtask extract
[2023-03-05T00:36:24.758+0000] {task_command.py:388} INFO - Running <TaskInstance: sl_covid_dag_v1.extract scheduled__2023-03-04T00:00:00+00:00 [running]> on host 00dcc0a33b20
[2023-03-05T00:36:24.982+0000] {taskinstance.py:1509} INFO - Exporting the following env vars:
AIRFLOW_CTX_DAG_OWNER=ishok
AIRFLOW_CTX_DAG_ID=sl_covid_dag_v1
AIRFLOW_CTX_TASK_ID=extract
AIRFLOW_CTX_EXECUTION_DATE=2023-03-04T00:00:00+00:00
AIRFLOW_CTX_TRY_NUMBER=6
AIRFLOW_CTX_DAG_RUN_ID=scheduled__2023-03-04T00:00:00+00:00
[2023-03-05T00:36:25.025+0000] {taskinstance.py:1768} ERROR - Task failed with exception
Traceback (most recent call last):
  File "/usr/local/lib/python3.7/urllib/request.py", line 1350, in do_open
    encode_chunked=req.has_header('Transfer-encoding'))
  File "/usr/local/lib/python3.7/http/client.py", line 1281, in request
    self._send_request(method, url, body, headers, encode_chunked)
  File "/usr/local/lib/python3.7/http/client.py", line 1327, in _send_request
    self.endheaders(body, encode_chunked=encode_chunked)
  File "/usr/local/lib/python3.7/http/client.py", line 1276, in endheaders
    self._send_output(message_body, encode_chunked=encode_chunked)
  File "/usr/local/lib/python3.7/http/client.py", line 1036, in _send_output
    self.send(msg)
  File "/usr/local/lib/python3.7/http/client.py", line 976, in send
    self.connect()
  File "/usr/local/lib/python3.7/http/client.py", line 1443, in connect
    super().connect()
  File "/usr/local/lib/python3.7/http/client.py", line 948, in connect
    (self.host,self.port), self.timeout, self.source_address)
  File "/usr/local/lib/python3.7/socket.py", line 707, in create_connection
    for res in getaddrinfo(host, port, 0, SOCK_STREAM):
  File "/usr/local/lib/python3.7/socket.py", line 752, in getaddrinfo
    for res in _socket.getaddrinfo(host, port, family, type, proto, flags):
socket.gaierror: [Errno -2] Name or service not known

During handling of the above exception, another exception occurred:

Traceback (most recent call last):
  File "/home/airflow/.local/lib/python3.7/site-packages/airflow/operators/python.py", line 175, in execute
    return_value = self.execute_callable()
  File "/home/airflow/.local/lib/python3.7/site-packages/airflow/operators/python.py", line 192, in execute_callable
    return self.python_callable(*self.op_args, **self.op_kwargs)
  File "/opt/airflow/dags/sl_covid_dag.py", line 15, in extract
    covid = pd.read_csv(spreadsheet_name)
  File "/home/airflow/.local/lib/python3.7/site-packages/pandas/util/_decorators.py", line 311, in wrapper
    return func(*args, **kwargs)
  File "/home/airflow/.local/lib/python3.7/site-packages/pandas/io/parsers/readers.py", line 586, in read_csv
    return _read(filepath_or_buffer, kwds)
  File "/home/airflow/.local/lib/python3.7/site-packages/pandas/io/parsers/readers.py", line 482, in _read
    parser = TextFileReader(filepath_or_buffer, **kwds)
  File "/home/airflow/.local/lib/python3.7/site-packages/pandas/io/parsers/readers.py", line 811, in __init__
    self._engine = self._make_engine(self.engine)
  File "/home/airflow/.local/lib/python3.7/site-packages/pandas/io/parsers/readers.py", line 1040, in _make_engine
    return mapping[engine](self.f, **self.options)  # type: ignore[call-arg]
  File "/home/airflow/.local/lib/python3.7/site-packages/pandas/io/parsers/c_parser_wrapper.py", line 51, in __init__
    self._open_handles(src, kwds)
  File "/home/airflow/.local/lib/python3.7/site-packages/pandas/io/parsers/base_parser.py", line 229, in _open_handles
    errors=kwds.get("encoding_errors", "strict"),
  File "/home/airflow/.local/lib/python3.7/site-packages/pandas/io/common.py", line 614, in get_handle
    storage_options=storage_options,
  File "/home/airflow/.local/lib/python3.7/site-packages/pandas/io/common.py", line 312, in _get_filepath_or_buffer
    with urlopen(req_info) as req:
  File "/home/airflow/.local/lib/python3.7/site-packages/pandas/io/common.py", line 212, in urlopen
    return urllib.request.urlopen(*args, **kwargs)
  File "/usr/local/lib/python3.7/urllib/request.py", line 222, in urlopen
    return opener.open(url, data, timeout)
  File "/usr/local/lib/python3.7/urllib/request.py", line 525, in open
    response = self._open(req, data)
  File "/usr/local/lib/python3.7/urllib/request.py", line 543, in _open
    '_open', req)
  File "/usr/local/lib/python3.7/urllib/request.py", line 503, in _call_chain
    result = func(*args)
  File "/usr/local/lib/python3.7/urllib/request.py", line 1393, in https_open
    context=self._context, check_hostname=self._check_hostname)
  File "/usr/local/lib/python3.7/urllib/request.py", line 1352, in do_open
    raise URLError(err)
urllib.error.URLError: <urlopen error [Errno -2] Name or service not known>
[2023-03-05T00:36:25.069+0000] {taskinstance.py:1323} INFO - Marking task as FAILED. dag_id=sl_covid_dag_v1, task_id=extract, execution_date=20230304T000000, start_date=20230305T003624, end_date=20230305T003625
[2023-03-05T00:36:25.103+0000] {standard_task_runner.py:105} ERROR - Failed to execute job 39 for task extract (<urlopen error [Errno -2] Name or service not known>; 30770)
[2023-03-05T00:36:25.169+0000] {local_task_job.py:208} INFO - Task exited with return code 1
[2023-03-05T00:36:25.223+0000] {taskinstance.py:2578} INFO - 0 downstream tasks scheduled from follow-on schedule check
